Workbook

Sheet Affordability Calculator
A1: TEREPAY AFFORDABILITY CALCULATOR
A2: CCCFA Compliance Tool - v1.0
A4: SECTION A: CUSTOMER INFORMATION
A5: Customer Name:
A6: Loan Amount Requested:
A7: Loan Purpose:
A8: Assessment Date: | B8: =TODAY() -> 46055
A9: Assessed By:
A11: Employment & Visa Details
A12: Employment Status: | B12: Permanent/Fixed-term/Casual
A13: Employer:
A14: Time with Employer (months):
A16: Visa Status: | B16: NZ Citizen/Resident or Temporary
A17: Visa Type (if temporary):
A18: Visa Expiry Date:
A19: Valid 3+ months beyond loan? | B19: YES/NO
A21: Centrix Report Details
A22: Report Number:
A23: Report Date:
A24: First Transaction Date:
A25: Days of Data: | B25: =B23-B24 -> 0
A26: 90+ Days? | B26: =IF(B25>=90,"✓ PASS","✗ FAIL - DECLINE") -> ✗ FAIL - DECLINE
A27: ⚠️ CRITICAL: If less than 90 days, DECLINE application
A29: SECTION B: INCOME VERIFICATION
A30: Income Source | B30: Centrix Amount ($/fn) | C30: Verified (Y/N) | D30: Adjusted Amount ($/fn)
A31: Salary/Wages | D31: =IF(B31="","",B31)
A32: Bonuses | D32: =IF(B32="","",B32)
A33: Rental Income | D33: =IF(B33="","",B33)
A34: Benefits/WINZ | D34: =IF(B34="","",B34)
A35: Partner Income | D35: =IF(B35="","",B35)
A36: Other Income | D36: =IF(B36="","",B36)
A37: TOTAL VERIFIED INCOME | D37: =SUM(D31:D36) -> 0
A39: SECTION C: EXPENSE VERIFICATION & ADJUSTMENTS
A40: Expense Category | B40: Centrix ($/fn) | C40: Benchmark ($/fn) | D40: Final Amount ($/fn)
A41: ESSENTIAL LIVING
A42: Food & Groceries | C42: =Benchmarks!B4 -> Per Fortnight | D42: =IF(B42="",C42,MAX(B42,C42)) -> Per Fortnight
A43: Utilities (power, water, internet) | C43: =Benchmarks!B5 -> 280 | D43: =IF(B43="",C43,MAX(B43,C43)) -> 280
A44: Personal expenses (clothing, footwear) | C44: =Benchmarks!B6 -> 100 | D44: =IF(B44="",C44,MAX(B44,C44)) -> 100
A45: Transport (fuel, WoF/rego, maintenance) | C45: =Benchmarks!B7 -> 80 | D45: =IF(B45="",C45,MAX(B45,C45)) -> 80
A46: Medical (GP, prescriptions) | C46: =Benchmarks!B8 -> 200 | D46: =IF(B46="",C46,MAX(B46,C46)) -> 200
...

Sheet Benchmarks
A1: TEREPAY EXPENSE BENCHMARKS
A2: Auckland 2026 - Single Adult (Adjust for household size)
A4: Category | B4: Per Fortnight | C4: Notes
A5: Food & Groceries | B5: 280 | C5: Range: $240-320
A6: Utilities | B6: 100 | C6: Range: $80-120 (power, water, internet)
A7: Personal/Clothing | B7: 80 | C7: Range: $60-100
A8: Transport (Car) | B8: 200 | C8: Range: $160-240 (fuel, WOF, rego, maintenance)
A9: Medical | B9: 60 | C9: Range: $40-80 (GP visits, prescriptions)
A10: Childcare | B10: 0 | C10: Preschool: $400-800, School age: $100-200
A13: HOUSEHOLD SIZE MULTIPLIERS
A14: 2 adults | B14: 1.5x
A15: 2 adults + 1 child | B15: 1.8x
A16: 2 adults + 2 children | B16: 2.0x
A17: Each additional person | B17: +0.3x

Sheet Quick Guide
A1: TEREPAY AFFORDABILITY CALCULATOR
A2: Quick Reference Guide
A4: HOW TO USE THIS CALCULATOR
A5: 1. Complete customer information (Section A)
A6: 2. Enter income from Centrix and verify (Section B)
A7: 3. Enter expenses from Centrix (Section C)
A8: - Benchmarks auto-populate - use higher of Centrix or benchmark
A9: - Add any additional expenses not in Centrix
A10: 4. Enter loan amount requested (Section D)
A11: - All calculations are automatic
A12: 5. Review Final Available Surplus
A13: - Positive = potentially affordable
... A17: LOAN PAYMENT QUICK REFERENCE
A18: Loan Amount | B18: Fortnightly Payment | C18: Total Repayment
A19: 200 | B19: 52.35 | C19: 209.4
A20: 500 | B20: 130.88 | C20: 523.5
A21: 800 | B21: 209.4 | C21: 837.6
A22: 1000 | B22: 261.75 | C22: 1047
A23: 1200 | B23: 314.1 | C23: 1256.4
A24: 1500 | B24: 392.63 | C24: 1570.5
A25: 2000 | B25: 523.5 | C25: 2094
A27: INSTANT DECLINE REASONS
A28: • Less than 90 days transaction data
A29: • Visa expiring before loan completion
A30: • Final Available Surplus ≤ $0
A31: • Cannot verify income
A32: • Recent payment defaults (90 days)
A33: • Loan purpose: overseas remittances
A34: • Loan purpose: planned expenses (visa, celebrations)
A36: AFFORDABILITY DECISION GUIDE
A37: Final Surplus | B37: Interpretation | C37: Action
A38: > $100/fortnight | B38: ✓ Likely Affordable | C38: Proceed - subject to other checks
A39: $50-$100/fortnight | B39: ⚠ Marginal | C39: Careful consideration needed
A40: $0-$50/fortnight | B40: ⚠ High Risk | C40: Likely substantial hardship
A41: < $0 (negative) | B41: ✗ Not Affordable | C41: MUST DECLINE
